<?xml version="1.0" ?>
<robot name="slidingboxes">
  <joint name="slidingboxes__link_0_JOINT_1" type="prismatic">
    <parent link="slidingboxes__link_0"/>
    <child link="slidingboxes__link_0_clone_0"/>
    <origin xyz="0     0     0.3362" rpy="0 0 0"/>
    <axis xyz="0 1 0"/>
    <limit lower="-1.79769e+308" upper="1.79769e+308" effort="-1.0" velocity="-1.0"/>
  </joint>
  <joint name="slidingboxes__link_0_clone_JOINT_0" type="prismatic">
    <parent link="slidingboxes__link_0_clone"/>
    <child link="slidingboxes__link_0"/>
    <origin xyz="0      0      0.04053" rpy="0 0 0"/>
    <axis xyz="1 0 0"/>
    <limit lower="-1.79769e+308" upper="1.79769e+308" effort="-1.0" velocity="-1.0"/>
  </joint>
  <link name="slidingboxes__link_0">
    <inertial>
      <mass value="1"/>
      <origin xyz="0 0 0" rpy="0 0 0"/>
      <inertia ixx="0.166667" ixy="0" ixz="0" iyy="0.166667" iyz="0" izz="0.166667"/>
    </inertial>
    <collision name="slidingboxes__collision_3">
      <origin xyz="0 0 0" rpy="0 0 0"/>
      <geometry>
        <box size="0.5 0.5 0.25"/>
      </geometry>
    </collision>
    <visual name="slidingboxes__visual">
      <origin xyz="0 0 0" rpy="0 0 0"/>
      <geometry>
        <box size="0.5 0.5 0.25"/>
      </geometry>
    </visual>
  </link>
  <link name="slidingboxes__link_0_clone">
    <inertial>
      <mass value="1"/>
      <origin xyz="0 0 0" rpy="0 0 0"/>
      <inertia ixx="0.166667" ixy="0" ixz="0" iyy="0.166667" iyz="0" izz="0.166667"/>
    </inertial>
    <collision name="slidingboxes__collision_1">
      <origin xyz="0       0      -0.41726" rpy="0 0 0"/>
      <geometry>
        <box size="0.5 0.5 0.5"/>
      </geometry>
    </collision>
    <visual name="slidingboxes__visual">
      <origin xyz="0       0      -0.41726" rpy="0 0 0"/>
      <geometry>
        <box size="0.5 0.5 0.5"/>
      </geometry>
    </visual>
  </link>
  <link name="slidingboxes__link_0_clone_0">
    <inertial>
      <mass value="1"/>
      <origin xyz="0 0 0" rpy="0 0 0"/>
      <inertia ixx="0.166667" ixy="0" ixz="0" iyy="0.166667" iyz="0" izz="0.166667"/>
    </inertial>
    <collision name="slidingboxes__collision_3">
      <origin xyz="0 0 0" rpy="0 0 0"/>
      <geometry>
        <box size="0.5 0.5 0.25"/>
      </geometry>
    </collision>
    <visual name="slidingboxes__visual">
      <origin xyz="0 0 0" rpy="0 0 0"/>
      <geometry>
        <box size="0.5 0.5 0.25"/>
      </geometry>
    </visual>
  </link>
</robot>
